{"timestamp": "2025-06-30T07:09:30.181153", "level": "ERROR", "logger": "src.middleware.error_handler", "message": "Unexpected error: 'HTTPException' object is not callable", "module": "error_handler", "function": "error_handler_middleware", "line": 116, "exception": {"type": "TypeError", "message": "'HTTPException' object is not callable", "traceback": ["Traceback (most recent call last):\n", "  File \"/Users/jimmylam/Documents/security/codebase_scanner/backend/venv/lib/python3.13/site-packages/starlette/_exception_handler.py\", line 42, in wrapped_app\n    await app(scope, receive, sender)\n", "  File \"/Users/jimmylam/Documents/security/codebase_scanner/backend/venv/lib/python3.13/site-packages/starlette/routing.py\", line 714, in __call__\n    await self.middleware_stack(scope, receive, send)\n", "  File \"/Users/jimmylam/Documents/security/codebase_scanner/backend/venv/lib/python3.13/site-packages/starlette/routing.py\", line 764, in app\n    await self.default(scope, receive, send)\n", "  File \"/Users/jimmylam/Documents/security/codebase_scanner/backend/venv/lib/python3.13/site-packages/starlette/routing.py\", line 650, in not_found\n    raise HTTPException(status_code=404)\n", "starlette.exceptions.HTTPException: 404: Not Found\n", "\nDuring handling of the above exception, another exception occurred:\n\n", "Traceback (most recent call last):\n", "  File \"/Users/jimmylam/Documents/security/codebase_scanner/backend/src/middleware/error_handler.py\", line 68, in error_handler_middleware\n    return await call_next(request)\n                 ~~~~~~~~~^^^^^^^^^\n", "TypeError: 'HTTPException' object is not callable\n"]}}
